Workbook

Sheet Cover & Instructions
A1: talktü — 12-Month Financial Model (Aug 2026 – Jul 2027) — NGN, 3-Scenario Edition
A2: Prepared by Zacharie Hossana Dayang — Finance Associate Intern
B4: PURPOSE
B5: This workbook is a working 12-month financial model for talktü, built to satisfy the first 30-day deliverable of the Finance Associate Intern role: a functional financial model covering budget, revenue forecast and cash flow, in Naira (₦). It goes further than a single forecast: it adds a Conservative / Base / Optimistic Scenario Analysis, the kind of sensitivity thinking used in quantitative finance, so leadership can see a range of outcomes, not just one guess. It is designed to be realistic (grounded in typical African B2C/B2B edtech unit economics), innovative (blended B2C + B2B + grant revenue mix, marketing spend tied to revenue, and scenario-based risk analysis) and easy to present to non-finance stakeholders.
B10: HOW TO USE THIS FILE
B11: 1. Assumptions — replace every blue/yellow input with talktü's real numbers (pricing, current user base, actual salaries, current cash balance) as soon as you get them from Sarah / the Finance Lead.
B12: 2. Revenue Model — auto-calculates Parent App, School Platform, Assessment and Grant revenue from the Assumptions tab. Do not type over the black formula cells.
B13: 3. OpEx — auto-calculates salaries, tech, marketing and admin costs, including a variable cost that scales with users (tech) and with revenue (marketing reinvestment).
B14: 4. Cash Flow — rolls beginning/ending cash forward month by month and estimates runway.
B15: 5. P&L Summary — a clean monthly + full-year income statement, ready to paste into slides.
B16: 6. Scenario Analysis — Conservative / Base / Optimistic side by side: revenue, cash and runway under three different growth and retention assumptions.
B17: 7. Dashboard — charts + a KPI box, built for a 5-minute stakeholder presentation, including the 3-scenario cash comparison.
B19: COLOR LEGEND
B20: Blue text on yellow fill | C20: Hardcoded input / assumption — safe and expected to edit
B21: Black text | C21: Formula — do not overwrite
B22: Green text | C22: Link pulling a value from another sheet
B23: Bold on light-blue fill | C23: Subtotal / Total row
B25: KEY ASSUMPTIONS TO VALIDATE FIRST
B26: All figures below are realistic placeholders benchmarked against comparable early-stage African B2C/B2B edtech ventures — not talktü's actual books. Flag this clearly whenever you present the model, and swap in real numbers the moment you have them (current cash balance, current subscriber count, actual salaries, and actual school pipeline are the highest-priority ones).

Sheet Dashboard
A1: talktü — Financial Model Dashboard (FY Aug 2026 – Jul 2027)
A2: Illustrative model — replace Assumptions with actuals before external presentation.
A5: Full-Year Revenue | D5: Full-Year OpEx | G5: Full-Year Net Result | J5: Estimated Runway | M5: Funding Need (Yr 1)
A6: ='P&L Summary'!N10 -> 1.5513928e+08 | D6: ='P&L Summary'!N18 -> 3.193034e+08 | G6: ='P&L Summary'!N20 -> -1.6416411e+08 | J6: ='Cash Flow'!B14 -> 5.0867182 | M6: ='Cash Flow'!B16 -> 91389363
A64: Full-Year Scenario Summary
B65: Conservative | C65: Base | D65: Optimistic
A66: Full-Year Revenue (₦) | B66: ='Scenario Analysis'!B57 -> 39237591 | C66: ='Scenario Analysis'!C57 -> 1.5513928e+08 | D66: ='Scenario Analysis'!D57 -> 2.1470797e+08
A67: Full-Year OpEx (₦) | B67: ='Scenario Analysis'!B58 -> 3.0858988e+08 | C67: ='Scenario Analysis'!C58 -> 3.193034e+08 | D67: ='Scenario Analysis'!D58 -> 3.255074e+08
A68: Full-Year Net Result (₦) | B68: ='Scenario Analysis'!B59 -> -2.6935229e+08 | C68: ='Scenario Analysis'!C59 -> -1.6416411e+08 | D68: ='Scenario Analysis'!D59 -> -1.1079943e+08
A69: Ending Cash — Jul-27 (₦) | B69: ='Scenario Analysis'!B60 -> -1.9435229e+08 | C69: ='Scenario Analysis'!C60 -> -89164112 | D69: ='Scenario Analysis'!D60 -> -35799430
A70: Estimated Runway (months) | B70: ='Scenario Analysis'!B62 -> 3.3380327 | C70: ='Scenario Analysis'!C62 -> 5.0867182 | D70: ='Scenario Analysis'!D62 -> 6.4883341

Sheet Assumptions
A1: Key Drivers & Assumptions
A2: Column B = Base case (used everywhere). Columns C/D = Conservative / Optimistic, used only in the Scenario Analysis tab. Edit only blue/yellow cells.
B3: BASE | C3: CONSERVATIVE | D3: OPTIMISTIC
A4: GENERAL
A5: Model Start Month | B5: Aug-2026
A6: Currency | B6: NGN (₦)
A7: Starting Cash Balance (₦) | B7: 75000000 | E7: Replace with talktü's actual bank balance on Day 1. (~₦75M ≈ $50,000 at ₦1,500/$1.)
A9: PARENT APP — B2C SUBSCRIPTIONS
A10: New App Downloads — Month 1 | B10: 800 | E10: New free installs of the parent app in the first month.
A11: Monthly Download Growth Rate | B11: 0.08 | C11: 0.04 | D11: 0.12 | E11: Month-over-month growth in new downloads (organic + marketing-driven).
A12: Free-to-Premium Conversion Rate | B12: 0.05 | C12: 0.03 | D12: 0.07 | E12: Share of each month's new downloads that upgrade to a paid plan.
A13: Premium Subscription Price (₦/month) | B13: 4500 | E13: Benchmark: comparable African parent-learning apps price ₦3,000-7,500/month.
A14: Premium Monthly Churn Rate | B14: 0.04 | C14: 0.06 | D14: 0.03 | E14: Share of paying subscribers who cancel each month.
A16: SCHOOL PLATFORM — B2B
A17: New Schools Onboarded — Month 1 | B17: 3 | E17: Pilot schools signed at launch.
A18: New Schools Added per Month (from Month 2) | B18: 2 | C18: 1 | D18: 3 | E18: Steady-state sales pace once the pipeline is running.
A19: Price per School (₦/month) | B19: 225000 | E19: Flat classroom-tools licence fee per school.
A20: School Monthly Churn Rate | B20: 0.01 | C20: 0.02 | D20: 0.005 | E20: B2B contracts churn far slower than consumer subscriptions.
A22: ASSESSMENTS
A23: Assessments Sold — Month 1 | B23: 50 | E23: Paid developmental/learning assessments.
A24: Monthly Growth Rate — Assessments | B24: 0.05 | C24: 0.02 | D24: 0.08
A25: Price per Assessment (₦) | B25: 15000
A27: GRANTS & PARTNERSHIPS
A28: Quarterly Grant / Partner Inflow (₦) | B28: 22500000 | C28: 0 | D28: 30000000 | E28: Booked in Month 3, 6, 9 and 12. Conservative assumes no grant secured yet.
A30: OPERATING EXPENSES
A31: Core Team Monthly Salaries (₦) | B31: 18000000 | E31: All-in payroll for the core team (product, eng, learning, ops).
A32: Quarterly Salary Growth Rate | B32: 0.03 | E32: Step-up every 3 months (raises / new hires).
A33: Tech & Hosting — Base (₦/month) | B33: 2250000
A34: Tech & Hosting — Variable Cost per App User (₦) | B34: 75 | E34: Cloud/infra cost that scales with the cumulative user base.
A35: Marketing — Base (₦/month) | B35: 1500000
A36: Marketing — % of Revenue Reinvested | B36: 0.08 | E36: Growth marketing spend scales with revenue performance.
A37: Admin & Legal (₦/month) | B37: 1200000
A38: Contingency (% of OpEx) | B38: 0.05 | E38: Buffer for unplanned costs — standard for early-stage startups.

Sheet Revenue Model
A1: Revenue Model — Monthly Build
A2: All cells below are formulas driven by the Assumptions tab. Do not type over black cells.
B3: Aug-26 | C3: Sep-26 | D3: Oct-26 | E3: Nov-26 | F3: Dec-26 | G3: Jan-27 | H3: Feb-27 | I3: Mar-27 | J3: Apr-27 | K3: May-27 | L3: Jun-27 | M3: Jul-27
A5: PARENT APP — B2C SUBSCRIPTIONS
A6: New Downloads | B6: =Assumptions!$B$10 -> 800 | C6: =B6*(1+Assumptions!$B$11) -> 864 | D6: =C6*(1+Assumptions!$B$11) -> 933.12 | E6: =D6*(1+Assumptions!$B$11) -> 1007.7696 | F6: =E6*(1+Assumptions!$B$11) -> 1088.3912 | G6: =F6*(1+Assumptions!$B$11) -> 1175.4625 | H6: =G6*(1+Assumptions!$B$11) -> 1269.4995 | I6: =H6*(1+Assumptions!$B$11) -> 1371.0594 | J6: =I6*(1+Assumptions!$B$11) -> 1480.7442 | ... M6: =L6*(1+Assumptions!$B$11) -> 1865.3112
A7: Cumulative App Users (all-time downloads) | B7: =B6 -> 800 | C7: =B7+C6 -> 1664 | D7: =C7+D6 -> 2597.12 | E7: =D7+E6 -> 3604.8896 | F7: =E7+F6 -> 4693.2808 | G7: =F7+G6 -> 5868.7432 | H7: =G7+H6 -> 7138.2427 | I7: =H7+I6 -> 8509.3021 | J7: =I7+J6 -> 9990.0463 | ... M7: =L7+M6 -> 15181.701
A8: New Premium Subscribers | B8: =B6*Assumptions!$B$12 -> 40 | C8: =C6*Assumptions!$B$12 -> 43.2 | D8: =D6*Assumptions!$B$12 -> 46.656 | E8: =E6*Assumptions!$B$12 -> 50.38848 | F8: =F6*Assumptions!$B$12 -> 54.419558 | G8: =G6*Assumptions!$B$12 -> 58.773123 | H8: =H6*Assumptions!$B$12 -> 63.474973 | I8: =I6*Assumptions!$B$12 -> 68.552971 | ... M8: =M6*Assumptions!$B$12 -> 93.26556
A9: Active Premium Subscribers | B9: =B8 -> 40 | C9: =B9*(1-Assumptions!$B$14)+C8 -> 81.6 | D9: =C9*(1-Assumptions!$B$14)+D8 -> 124.992 | E9: =D9*(1-Assumptions!$B$14)+E8 -> 170.3808 | F9: =E9*(1-Assumptions!$B$14)+F8 -> 217.98513 | G9: =F9*(1-Assumptions!$B$14)+G8 -> 268.03884 | H9: =G9*(1-Assumptions!$B$14)+H8 -> 320.79226 | I9: =H9*(1-Assumptions!$B$14)+I8 -> 376.51354 | J9: =I9*(1-Assumptions!$B$14)+J8 -> 435.49021 | ... M9: =L9*(1-Assumptions!$B$14)+M8 -> 635.15345
A10: Premium Revenue ($) | B10: =B9*Assumptions!$B$13 -> 180000 | C10: =C9*Assumptions!$B$13 -> 367200 | D10: =D9*Assumptions!$B$13 -> 562464 | E10: =E9*Assumptions!$B$13 -> 766713.6 | F10: =F9*Assumptions!$B$13 -> 980933.07 | G10: =G9*Assumptions!$B$13 -> 1206174.8 | H10: =H9*Assumptions!$B$13 -> 1443565.2 | I10: =I9*Assumptions!$B$13 -> 1694310.9 | ... M10: =M9*Assumptions!$B$13 -> 2858190.5
A12: SCHOOL PLATFORM — B2B
A13: New Schools Added | B13: =Assumptions!$B$17 -> 3 | C13: =Assumptions!$B$18 -> 2 | D13: =Assumptions!$B$18 -> 2 | E13: =Assumptions!$B$18 -> 2 | F13: =Assumptions!$B$18 -> 2 | G13: =Assumptions!$B$18 -> 2 | H13: =Assumptions!$B$18 -> 2 | I13: =Assumptions!$B$18 -> 2 | J13: =Assumptions!$B$18 -> 2 | ... M13: =Assumptions!$B$18 -> 2
A14: Active Schools | B14: =B13 -> 3 | C14: =B14*(1-Assumptions!$B$20)+C13 -> 4.97 | D14: =C14*(1-Assumptions!$B$20)+D13 -> 6.9203 | E14: =D14*(1-Assumptions!$B$20)+E13 -> 8.851097 | F14: =E14*(1-Assumptions!$B$20)+F13 -> 10.762586 | G14: =F14*(1-Assumptions!$B$20)+G13 -> 12.65496 | H14: =G14*(1-Assumptions!$B$20)+H13 -> 14.528411 | I14: =H14*(1-Assumptions!$B$20)+I13 -> 16.383126 | J14: =I14*(1-Assumptions!$B$20)+J13 -> 18.219295 | ... M14: =L14*(1-Assumptions!$B$20)+M13 -> 23.618364
A15: School Platform Revenue ($) | B15: =B14*Assumptions!$B$19 -> 675000 | C15: =C14*Assumptions!$B$19 -> 1118250 | D15: =D14*Assumptions!$B$19 -> 1557067.5 | E15: =E14*Assumptions!$B$19 -> 1991496.8 | F15: =F14*Assumptions!$B$19 -> 2421581.9 | G15: =G14*Assumptions!$B$19 -> 2847366 | H15: =H14*Assumptions!$B$19 -> 3268892.4 | I15: =I14*Assumptions!$B$19 -> 3686203.5 | ... M15: =M14*Assumptions!$B$19 -> 5314131.9
A17: ASSESSMENTS
A18: Assessments Sold | B18: =Assumptions!$B$23 -> 50 | C18: =B18*(1+Assumptions!$B$24) -> 52.5 | D18: =C18*(1+Assumptions!$B$24) -> 55.125 | E18: =D18*(1+Assumptions!$B$24) -> 57.88125 | F18: =E18*(1+Assumptions!$B$24) -> 60.775312 | G18: =F18*(1+Assumptions!$B$24) -> 63.814078 | H18: =G18*(1+Assumptions!$B$24) -> 67.004782 | I18: =H18*(1+Assumptions!$B$24) -> 70.355021 | J18: =I18*(1+Assumptions!$B$24) -> 73.872772 | ... M18: =L18*(1+Assumptions!$B$24) -> 85.516968
A19: Assessment Revenue ($) | B19: =B18*Assumptions!$B$25 -> 750000 | C19: =C18*Assumptions!$B$25 -> 787500 | D19: =D18*Assumptions!$B$25 -> 826875 | E19: =E18*Assumptions!$B$25 -> 868218.75 | F19: =F18*Assumptions!$B$25 -> 911629.69 | G19: =G18*Assumptions!$B$25 -> 957211.17 | H19: =H18*Assumptions!$B$25 -> 1005071.7 | I19: =I18*Assumptions!$B$25 -> 1055325.3 | ... M19: =M18*Assumptions!$B$25 -> 1282754.5
A21: GRANTS & PARTNERSHIPS
A22: Grant / Partnership Revenue ($) | B22: =0 -> 0 | C22: =0 -> 0 | D22: =Assumptions!$B$28 -> 22500000 | E22: =0 -> 0 | F22: =0 -> 0 | G22: =Assumptions!$B$28 -> 22500000 | H22: =0 -> 0 | I22: =0 -> 0 | J22: =Assumptions!$B$28 -> 22500000 | K22: =0 -> 0 | L22: =0 -> 0 | M22: =Assumptions!$B$28 -> 22500000
A24: TOTAL REVENUE ($) | B24: =B10+B15+B19+B22 -> 1605000 | C24: =C10+C15+C19+C22 -> 2272950 | D24: =D10+D15+D19+D22 -> 25446406 | E24: =E10+E15+E19+E22 -> 3626429.2 | F24: =F10+F15+F19+F22 -> 4314144.6 | G24: =G10+G15+G19+G22 -> 27510752 | H24: =H10+H15+H19+H22 -> 5717529.3 | I24: =I10+I15+I19+I22 -> 6435839.7 | ... M24: =M10+M15+M19+M22 -> 31955077

Sheet OpEx
A1: Operating Expenses — Monthly Build
A2: Salaries step up quarterly; Tech scales with users; Marketing scales with revenue.
B3: Aug-26 | C3: Sep-26 | D3: Oct-26 | E3: Nov-26 | F3: Dec-26 | G3: Jan-27 | H3: Feb-27 | I3: Mar-27 | J3: Apr-27 | K3: May-27 | L3: Jun-27 | M3: Jul-27
A5: Core Team Salaries ($) | B5: =Assumptions!$B$31 -> 18000000 | C5: =B5 -> 18000000 | D5: =C5 -> 18000000 | E5: =D5*(1+Assumptions!$B$32) -> 18540000 | F5: =E5 -> 18540000 | G5: =F5 -> 18540000 | H5: =G5*(1+Assumptions!$B$32) -> 19096200 | I5: =H5 -> 19096200 | J5: =I5 -> 19096200 | K5: =J5*(1+Assumptions!$B$32) -> 19669086 | L5: =K5 -> 19669086 | M5: =L5 -> 19669086
A6: Tech & Hosting ($) | B6: =Assumptions!$B$33+Assumptions!$B$34*'Revenue Model'!B7 -> 2310000 | C6: =Assumptions!$B$33+Assumptions!$B$34*'Revenue Model'!C7 -> 2374800 | D6: =Assumptions!$B$33+Assumptions!$B$34*'Revenue Model'!D7 -> 2444784 | E6: =Assumptions!$B$33+Assumptions!$B$34*'Revenue Model'!E7 -> 2520366.7 | F6: =Assumptions!$B$33+Assumptions!$B$34*'Revenue Model'!F7 -> 2601996.1 | G6: =Assumptions!$B$33+Assumptions!$B$34*'Revenue Model'!G7 -> 2690155.7 | H6: =Assumptions!$B$33+Assumptions!$B$34*'Revenue Model'!H7 -> 2785368.2 | I6: =Assumptions!$B$33+Assumptions!$B$34*'Revenue Model'!I7 -> 2888197.7 | ... M6: =Assumptions!$B$33+Assumptions!$B$34*'Revenue Model'!M7 -> 3388627.6
A7: Marketing ($) | B7: =Assumptions!$B$35+Assumptions!$B$36*'Revenue Model'!B24 -> 1628400 | C7: =Assumptions!$B$35+Assumptions!$B$36*'Revenue Model'!C24 -> 1681836 | D7: =Assumptions!$B$35+Assumptions!$B$36*'Revenue Model'!D24 -> 3535712.5 | E7: =Assumptions!$B$35+Assumptions!$B$36*'Revenue Model'!E24 -> 1790114.3 | F7: =Assumptions!$B$35+Assumptions!$B$36*'Revenue Model'!F24 -> 1845131.6 | G7: =Assumptions!$B$35+Assumptions!$B$36*'Revenue Model'!G24 -> 3700860.2 | H7: =Assumptions!$B$35+Assumptions!$B$36*'Revenue Model'!H24 -> 1957402.3 | I7: =Assumptions!$B$35+Assumptions!$B$36*'Revenue Model'!I24 -> 2014867.2 | ... M7: =Assumptions!$B$35+Assumptions!$B$36*'Revenue Model'!M24 -> 4056406.2
A8: Admin & Legal ($) | B8: =Assumptions!$B$37 -> 1200000 | C8: =Assumptions!$B$37 -> 1200000 | D8: =Assumptions!$B$37 -> 1200000 | E8: =Assumptions!$B$37 -> 1200000 | F8: =Assumptions!$B$37 -> 1200000 | G8: =Assumptions!$B$37 -> 1200000 | H8: =Assumptions!$B$37 -> 1200000 | I8: =Assumptions!$B$37 -> 1200000 | ... M8: =Assumptions!$B$37 -> 1200000
A9: Subtotal Before Contingency ($) | B9: =SUM(B5:B8) -> 23138400 | C9: =SUM(C5:C8) -> 23256636 | D9: =SUM(D5:D8) -> 25180497 | E9: =SUM(E5:E8) -> 24050481 | F9: =SUM(F5:F8) -> 24187128 | G9: =SUM(G5:G8) -> 26131016 | H9: =SUM(H5:H8) -> 25038971 | I9: =SUM(I5:I8) -> 25199265 | ... M9: =SUM(M5:M8) -> 28314120
A10: Contingency ($) | B10: =B9*Assumptions!$B$38 -> 1156920 | C10: =C9*Assumptions!$B$38 -> 1162831.8 | D10: =D9*Assumptions!$B$38 -> 1259024.8 | E10: =E9*Assumptions!$B$38 -> 1202524.1 | F10: =F9*Assumptions!$B$38 -> 1209356.4 | G10: =G9*Assumptions!$B$38 -> 1306550.8 | H10: =H9*Assumptions!$B$38 -> 1251948.5 | I10: =I9*Assumptions!$B$38 -> 1259963.2 | ... M10: =M9*Assumptions!$B$38 -> 1415706
A12: TOTAL OPERATING EXPENSES ($) | B12: =B9+B10 -> 24295320 | C12: =C9+C10 -> 24419468 | D12: =D9+D10 -> 26439521 | E12: =E9+E10 -> 25253005 | F12: =F9+F10 -> 25396484 | G12: =G9+G10 -> 27437567 | H12: =H9+H10 -> 26290919 | I12: =I9+I10 -> 26459228 | ... M12: =M9+M10 -> 29729826

Sheet Cash Flow
A1: Cash Flow — Monthly Build
A2: Tracks beginning/ending cash and estimates runway at the current burn rate.
B3: Aug-26 | C3: Sep-26 | D3: Oct-26 | E3: Nov-26 | F3: Dec-26 | G3: Jan-27 | H3: Feb-27 | I3: Mar-27 | J3: Apr-27 | K3: May-27 | L3: Jun-27 | M3: Jul-27
A5: Beginning Cash ($) | B5: =Assumptions!$B$7 -> 75000000 | C5: =B10 -> 52309680 | D5: =C10 -> 30163162 | E5: =D10 -> 29170047 | F5: =E10 -> 7543471.4 | G5: =F10 -> -13538868 | H5: =G10 -> -13465683 | I5: =H10 -> -34039072 | J5: =I10 -> -54062461 | ... M5: =L10 -> -91389363
A6: Cash In — Total Revenue ($) | B6: ='Revenue Model'!B24 -> 1605000 | C6: ='Revenue Model'!C24 -> 2272950 | D6: ='Revenue Model'!D24 -> 25446406 | E6: ='Revenue Model'!E24 -> 3626429.2 | F6: ='Revenue Model'!F24 -> 4314144.6 | G6: ='Revenue Model'!G24 -> 27510752 | H6: ='Revenue Model'!H24 -> 5717529.3 | I6: ='Revenue Model'!I24 -> 6435839.7 | ... M6: ='Revenue Model'!M24 -> 31955077
A7: Cash Out — Total OpEx ($) | B7: =OpEx!B12 -> 24295320 | C7: =OpEx!C12 -> 24419468 | D7: =OpEx!D12 -> 26439521 | E7: =OpEx!E12 -> 25253005 | F7: =OpEx!F12 -> 25396484 | G7: =OpEx!G12 -> 27437567 | H7: =OpEx!H12 -> 26290919 | I7: =OpEx!I12 -> 26459228 | ... M7: =OpEx!M12 -> 29729826
A8: Net Cash Flow ($) | B8: =B6-B7 -> -22690320 | C8: =C6-C7 -> -22146518 | D8: =D6-D7 -> -993114.85 | E8: =E6-E7 -> -21626576 | F8: =F6-F7 -> -21082339 | G8: =G6-G7 -> 73185.312 | H8: =H6-H7 -> -20573390 | I8: =I6-I7 -> -20023388 | ... M8: =M6-M7 -> 2225251.2
A10: ENDING CASH BALANCE ($) | B10: =B5+B8 -> 52309680 | C10: =C5+C8 -> 30163162 | D10: =D5+D8 -> 29170047 | E10: =E5+E8 -> 7543471.4 | F10: =F5+F8 -> -13538868 | G10: =G5+G8 -> -13465683 | H10: =H5+H8 -> -34039072 | I10: =I5+I8 -> -54062461 | ... M10: =M5+M8 -> -89164112
A12: RUNWAY & FUNDING NEED (based on the first 6 months' average burn)
A13: Average Monthly Net Cash Flow — First 6 Months ($) | B13: =AVERAGE(B8:G8) -> -14744280
A14: Estimated Runway from Day 1 (Starting Cash / Avg Burn) | B14: =IF(B13>=0,"Cash-flow positive",Assumptions!$B$7/-B13) -> 5.0867182
A15: Minimum Cash Point in Year 1 ($) | B15: =MIN(B10:M10) -> -91389363
A16: Additional Funding Needed to Stay Cash-Positive All Year ($) | B16: =IF(B15<0,-B15,0) -> 91389363

Sheet P&L Summary
A1: Profit & Loss Summary
A2: Presentation-ready income statement — every figure links back to Revenue Model / OpEx.
B3: Aug-26 | C3: Sep-26 | D3: Oct-26 | E3: Nov-26 | F3: Dec-26 | G3: Jan-27 | H3: Feb-27 | I3: Mar-27 | J3: Apr-27 | K3: May-27 | L3: Jun-27 | M3: Jul-27 | N3: FY Total
A5: REVENUE
A6: Parent App — Premium Subscriptions | B6: ='Revenue Model'!B10 -> 180000 | C6: ='Revenue Model'!C10 -> 367200 | D6: ='Revenue Model'!D10 -> 562464 | E6: ='Revenue Model'!E10 -> 766713.6 | F6: ='Revenue Model'!F10 -> 980933.07 | G6: ='Revenue Model'!G10 -> 1206174.8 | H6: ='Revenue Model'!H10 -> 1443565.2 | I6: ='Revenue Model'!I10 -> 1694310.9 | ... M6: ='Revenue Model'!M10 -> 2858190.5 | N6: =SUM(B6:M6) -> 16800496
A7: School Platform | B7: ='Revenue Model'!B15 -> 675000 | C7: ='Revenue Model'!C15 -> 1118250 | D7: ='Revenue Model'!D15 -> 1557067.5 | E7: ='Revenue Model'!E15 -> 1991496.8 | F7: ='Revenue Model'!F15 -> 2421581.9 | G7: ='Revenue Model'!G15 -> 2847366 | H7: ='Revenue Model'!H15 -> 3268892.4 | I7: ='Revenue Model'!I15 -> 3686203.5 | ... M7: ='Revenue Model'!M15 -> 5314131.9 | N7: =SUM(B7:M7) -> 36400944
A8: Assessments | B8: ='Revenue Model'!B19 -> 750000 | C8: ='Revenue Model'!C19 -> 787500 | D8: ='Revenue Model'!D19 -> 826875 | E8: ='Revenue Model'!E19 -> 868218.75 | F8: ='Revenue Model'!F19 -> 911629.69 | G8: ='Revenue Model'!G19 -> 957211.17 | H8: ='Revenue Model'!H19 -> 1005071.7 | I8: ='Revenue Model'!I19 -> 1055325.3 | ... M8: ='Revenue Model'!M19 -> 1282754.5 | N8: =SUM(B8:M8) -> 11937845
A9: Grants & Partnerships | B9: ='Revenue Model'!B22 -> 0 | C9: ='Revenue Model'!C22 -> 0 | D9: ='Revenue Model'!D22 -> 22500000 | E9: ='Revenue Model'!E22 -> 0 | F9: ='Revenue Model'!F22 -> 0 | G9: ='Revenue Model'!G22 -> 22500000 | H9: ='Revenue Model'!H22 -> 0 | I9: ='Revenue Model'!I22 -> 0 | ... M9: ='Revenue Model'!M22 -> 22500000 | N9: =SUM(B9:M9) -> 90000000
A10: TOTAL REVENUE | B10: =SUM(B6:B9) -> 1605000 | C10: =SUM(C6:C9) -> 2272950 | D10: =SUM(D6:D9) -> 25446406 | E10: =SUM(E6:E9) -> 3626429.2 | F10: =SUM(F6:F9) -> 4314144.6 | G10: =SUM(G6:G9) -> 27510752 | H10: =SUM(H6:H9) -> 5717529.3 | I10: =SUM(I6:I9) -> 6435839.7 | ... M10: =SUM(M6:M9) -> 31955077 | N10: =SUM(B10:M10) -> 1.5513928e+08
A12: OPERATING EXPENSES
A13: Core Team Salaries | B13: =OpEx!B5 -> 18000000 | C13: =OpEx!C5 -> 18000000 | D13: =OpEx!D5 -> 18000000 | E13: =OpEx!E5 -> 18540000 | F13: =OpEx!F5 -> 18540000 | G13: =OpEx!G5 -> 18540000 | H13: =OpEx!H5 -> 19096200 | I13: =OpEx!I5 -> 19096200 | ... M13: =OpEx!M5 -> 19669086 | N13: =SUM(B13:M13) -> 225915858
A14: Tech & Hosting | B14: =OpEx!B6 -> 2310000 | C14: =OpEx!C6 -> 2374800 | D14: =OpEx!D6 -> 2444784 | E14: =OpEx!E6 -> 2520366.7 | F14: =OpEx!F6 -> 2601996.1 | G14: =OpEx!G6 -> 2690155.7 | H14: =OpEx!H6 -> 2785368.2 | I14: =OpEx!I6 -> 2888197.7 | ... M14: =OpEx!M6 -> 3388627.6 | N14: =SUM(B14:M14) -> 33371472
A15: Marketing | B15: =OpEx!B7 -> 1628400 | C15: =OpEx!C7 -> 1681836 | D15: =OpEx!D7 -> 3535712.5 | E15: =OpEx!E7 -> 1790114.3 | F15: =OpEx!F7 -> 1845131.6 | G15: =OpEx!G7 -> 3700860.2 | H15: =OpEx!H7 -> 1957402.3 | I15: =OpEx!I7 -> 2014867.2 | ... M15: =OpEx!M7 -> 4056406.2 | N15: =SUM(B15:M15) -> 30411143
A16: Admin & Legal | B16: =OpEx!B8 -> 1200000 | C16: =OpEx!C8 -> 1200000 | D16: =OpEx!D8 -> 1200000 | E16: =OpEx!E8 -> 1200000 | F16: =OpEx!F8 -> 1200000 | G16: =OpEx!G8 -> 1200000 | H16: =OpEx!H8 -> 1200000 | I16: =OpEx!I8 -> 1200000 | ... M16: =OpEx!M8 -> 1200000 | N16: =SUM(B16:M16) -> 14400000
A17: Contingency | B17: =OpEx!B10 -> 1156920 | C17: =OpEx!C10 -> 1162831.8 | D17: =OpEx!D10 -> 1259024.8 | E17: =OpEx!E10 -> 1202524.1 | F17: =OpEx!F10 -> 1209356.4 | G17: =OpEx!G10 -> 1306550.8 | H17: =OpEx!H10 -> 1251948.5 | I17: =OpEx!I10 -> 1259963.2 | ... M17: =OpEx!M10 -> 1415706 | N17: =SUM(B17:M17) -> 15204924
A18: TOTAL OPERATING EXPENSES | B18: =SUM(B13:B17) -> 24295320 | C18: =SUM(C13:C17) -> 24419468 | D18: =SUM(D13:D17) -> 26439521 | E18: =SUM(E13:E17) -> 25253005 | F18: =SUM(F13:F17) -> 25396484 | G18: =SUM(G13:G17) -> 27437567 | H18: =SUM(H13:H17) -> 26290919 | I18: =SUM(I13:I17) -> 26459228 | ... M18: =SUM(M13:M17) -> 29729826 | N18: =SUM(B18:M18) -> 3.193034e+08
A20: NET OPERATING RESULT ($) | B20: =B10-B18 -> -22690320 | C20: =C10-C18 -> -22146518 | D20: =D10-D18 -> -993114.85 | E20: =E10-E18 -> -21626576 | F20: =F10-F18 -> -21082339 | G20: =G10-G18 -> 73185.312 | H20: =H10-H18 -> -20573390 | I20: =I10-I18 -> -20023388 | ... M20: =M10-M18 -> 2225251.2 | N20: =SUM(B20:M20) -> -1.6416411e+08
A21: Net Margin (%) | B21: =IFERROR(B20/B10,0) -> -14.137271 | C21: =IFERROR(C20/C10,0) -> -9.743513 | D21: =IFERROR(D20/D10,0) -> -0.039027705 | E21: =IFERROR(E20/E10,0) -> -5.9636008 | F21: =IFERROR(F20/F10,0) -> -4.8867948 | G21: =IFERROR(G20/G10,0) -> 0.002660244 | H21: =IFERROR(H20/H10,0) -> -3.5983007 | I21: =IFERROR(I20/I10,0) -> -3.1112317 | ... N21: =IFERROR(N20/N10,0) -> -1.0581724

Sheet Scenario Analysis
A1: Scenario Analysis — Conservative / Base / Optimistic
A2: Re-runs the same engine as Revenue Model / OpEx / Cash Flow three times, using the Conservative / Base / Optimistic columns from Assumptions. This is the quantitative "range of outcomes" view, not a single-point guess.
A4: CONSERVATIVE CASE
B5: Aug-26 | C5: Sep-26 | D5: Oct-26 | E5: Nov-26 | F5: Dec-26 | G5: Jan-27 | H5: Feb-27 | I5: Mar-27 | J5: Apr-27 | K5: May-27 | L5: Jun-27 | M5: Jul-27
A6: New Downloads | B6: =Assumptions!$B$10 -> 800 | C6: =B6*(1+Assumptions!$C$11) -> 832 | D6: =C6*(1+Assumptions!$C$11) -> 865.28 | E6: =D6*(1+Assumptions!$C$11) -> 899.8912 | F6: =E6*(1+Assumptions!$C$11) -> 935.88685 | G6: =F6*(1+Assumptions!$C$11) -> 973.32232 | H6: =G6*(1+Assumptions!$C$11) -> 1012.2552 | I6: =H6*(1+Assumptions!$C$11) -> 1052.7454 | J6: =I6*(1+Assumptions!$C$11) -> 1094.8552 | ... M6: =L6*(1+Assumptions!$C$11) -> 1231.5632
A7: Cumulative App Users | B7: =B6 -> 800 | C7: =B7+C6 -> 1632 | D7: =C7+D6 -> 2497.28 | E7: =D7+E6 -> 3397.1712 | F7: =E7+F6 -> 4333.058 | G7: =F7+G6 -> 5306.3804 | H7: =G7+H6 -> 6318.6356 | I7: =H7+I6 -> 7371.381 | J7: =I7+J6 -> 8466.2362 | ... M7: =L7+M6 -> 12020.644
A8: Active Premium Subscribers | B8: =B6*Assumptions!$C$12 -> 24 | C8: =B8*(1-Assumptions!$C$14)+C6*Assumptions!$C$12 -> 47.52 | D8: =C8*(1-Assumptions!$C$14)+D6*Assumptions!$C$12 -> 70.6272 | E8: =D8*(1-Assumptions!$C$14)+E6*Assumptions!$C$12 -> 93.386304 | F8: =E8*(1-Assumptions!$C$14)+F6*Assumptions!$C$12 -> 115.85973 | G8: =F8*(1-Assumptions!$C$14)+G6*Assumptions!$C$12 -> 138.10782 | H8: =G8*(1-Assumptions!$C$14)+H6*Assumptions!$C$12 -> 160.189 | I8: =H8*(1-Assumptions!$C$14)+I6*Assumptions!$C$12 -> 182.16003 | J8: =I8*(1-Assumptions!$C$14)+J6*Assumptions!$C$12 -> 204.07608 | ... M8: =L8*(1-Assumptions!$C$14)+M6*Assumptions!$C$12 -> 270.02686
A9: Premium Revenue (₦) | B9: =B8*Assumptions!$B$13 -> 108000 | C9: =C8*Assumptions!$B$13 -> 213840 | D9: =D8*Assumptions!$B$13 -> 317822.4 | E9: =E8*Assumptions!$B$13 -> 420238.37 | F9: =F8*Assumptions!$B$13 -> 521368.79 | G9: =G8*Assumptions!$B$13 -> 621485.18 | H9: =H8*Assumptions!$B$13 -> 720850.52 | I9: =I8*Assumptions!$B$13 -> 819720.12 | ... M9: =M8*Assumptions!$B$13 -> 1215120.9
A10: Active Schools | B10: =Assumptions!$B$17 -> 3 | C10: =B10*(1-Assumptions!$C$20)+Assumptions!$C$18 -> 3.94 | D10: =C10*(1-Assumptions!$C$20)+Assumptions!$C$18 -> 4.8612 | E10: =D10*(1-Assumptions!$C$20)+Assumptions!$C$18 -> 5.763976 | F10: =E10*(1-Assumptions!$C$20)+Assumptions!$C$18 -> 6.6486965 | G10: =F10*(1-Assumptions!$C$20)+Assumptions!$C$18 -> 7.5157226 | H10: =G10*(1-Assumptions!$C$20)+Assumptions!$C$18 -> 8.3654081 | I10: =H10*(1-Assumptions!$C$20)+Assumptions!$C$18 -> 9.1980999 | J10: =I10*(1-Assumptions!$C$20)+Assumptions!$C$18 -> 10.014138 | ... M10: =L10*(1-Assumptions!$C$20)+Assumptions!$C$18 -> 12.365627
A11: School Revenue (₦) | B11: =B10*Assumptions!$B$19 -> 675000 | C11: =C10*Assumptions!$B$19 -> 886500 | D11: =D10*Assumptions!$B$19 -> 1093770 | E11: =E10*Assumptions!$B$19 -> 1296894.6 | F11: =F10*Assumptions!$B$19 -> 1495956.7 | G11: =G10*Assumptions!$B$19 -> 1691037.6 | H11: =H10*Assumptions!$B$19 -> 1882216.8 | I11: =I10*Assumptions!$B$19 -> 2069572.5 | ... M11: =M10*Assumptions!$B$19 -> 2782266
A12: Assessment Revenue (₦) | B12: =Assumptions!$B$23*Assumptions!$B$25 -> 750000 | C12: =B12*(1+Assumptions!$C$24) -> 765000 | D12: =C12*(1+Assumptions!$C$24) -> 780300 | E12: =D12*(1+Assumptions!$C$24) -> 795906 | F12: =E12*(1+Assumptions!$C$24) -> 811824.12 | G12: =F12*(1+Assumptions!$C$24) -> 828060.6 | H12: =G12*(1+Assumptions!$C$24) -> 844621.81 | I12: =H12*(1+Assumptions!$C$24) -> 861514.25 | J12: =I12*(1+Assumptions!$C$24) -> 878744.54 | ... M12: =L12*(1+Assumptions!$C$24) -> 932530.73
A13: Grant Revenue (₦) | B13: =0 -> 0 | C13: =0 -> 0 | D13: =Assumptions!$C$28 -> 0 | E13: =0 -> 0 | F13: =0 -> 0 | G13: =Assumptions!$C$28 -> 0 | H13: =0 -> 0 | I13: =0 -> 0 | J13: =Assumptions!$C$28 -> 0 | K13: =0 -> 0 | L13: =0 -> 0 | M13: =Assumptions!$C$28 -> 0
A14: TOTAL REVENUE (₦) | B14: =B9+B11+B12+B13 -> 1533000 | C14: =C9+C11+C12+C13 -> 1865340 | D14: =D9+D11+D12+D13 -> 2191892.4 | E14: =E9+E11+E12+E13 -> 2513039 | F14: =F9+F11+F12+F13 -> 2829149.6 | G14: =G9+G11+G12+G13 -> 3140583.4 | H14: =H9+H11+H12+H13 -> 3447689.2 | I14: =I9+I11+I12+I13 -> 3750806.9 | ... M14: =M9+M11+M12+M13 -> 4929917.6
A15: TOTAL OPEX (₦) | B15: =(B18+(Assumptions!$B$33+Assumptions!$B$34*B7)+(Assumptions!$B$35+Assumptions!$B$36*B14)+Assumptions!$B$37)*(1+Assumptions!$B$38) -> 24289272 | C15: =(C18+(Assumptions!$B$33+Assumptions!$B$34*C7)+(Assumptions!$B$35+Assumptions!$B$36*C14)+Assumptions!$B$37)*(1+Assumptions!$B$38) -> 24382709 | D15: =(D18+(Assumptions!$B$33+Assumptions!$B$34*D7)+(Assumptions!$B$35+Assumptions!$B$36*D14)+Assumptions!$B$37)*(1+Assumptions!$B$38) -> 24478280 | E15: =(E18+(Assumptions!$B$33+Assumptions!$B$34*E7)+(Assumptions!$B$35+Assumptions!$B$36*E14)+Assumptions!$B$37)*(1+Assumptions!$B$38) -> 25143123 | F15: =(F18+(Assumptions!$B$33+Assumptions!$B$34*F7)+(Assumptions!$B$35+Assumptions!$B$36*F14)+Assumptions!$B$37)*(1+Assumptions!$B$38) -> 25243377 | G15: =(G18+(Assumptions!$B$33+Assumptions!$B$34*G7)+(Assumptions!$B$35+Assumptions!$B$36*G14)+Assumptions!$B$37)*(1+Assumptions!$B$38) -> 25346186 | H15: =(H18+(Assumptions!$B$33+Assumptions!$B$34*H7)+(Assumptions!$B$35+Assumptions!$B$36*H14)+Assumptions!$B$37)*(1+Assumptions!$B$38) -> 26035708 | I15: =(I18+(Assumptions!$B$33+Assumptions!$B$34*I7)+(Assumptions!$B$35+Assumptions!$B$36*I14)+Assumptions!$B$37)*(1+Assumptions!$B$38) -> 26144074 | ... M15: =(M18+(Assumptions!$B$33+Assumptions!$B$34*M7)+(Assumptions!$B$35+Assumptions!$B$36*M14)+Assumptions!$B$37)*(1+Assumptions!$B$38) -> 27210779
A16: Net Cash Flow (₦) | B16: =B14-B15 -> -22756272 | C16: =C14-C15 -> -22517369 | D16: =D14-D15 -> -22286387 | E16: =E14-E15 -> -22630084 | F16: =F14-F15 -> -22414227 | G16: =G14-G15 -> -22205603 | H16: =H14-H15 -> -22588019 | I16: =I14-I15 -> -22393267 | ... M16: =M14-M15 -> -22280862
A17: Ending Cash Balance (₦) | B17: =Assumptions!$B$7+B16 -> 52243728 | C17: =B17+C16 -> 29726359 | D17: =C17+D16 -> 7439972.1 | E17: =D17+E16 -> -15190111 | F17: =E17+F16 -> -37604339 | G17: =F17+G16 -> -59809942 | H17: =G17+H16 -> -82397961 | I17: =H17+I16 -> -1.0479123e+08 | J17: =I17+J16 -> -1.2699641e+08 | ... M17: =L17+M16 -> -1.9435229e+08
A18: (helper) Monthly Salaries (₦) | B18: =Assumptions!$B$31 -> 18000000 | C18: =B18 -> 18000000 | D18: =C18 -> 18000000 | E18: =D18*(1+Assumptions!$B$32) -> 18540000 | F18: =E18 -> 18540000 | G18: =F18 -> 18540000 | H18: =G18*(1+Assumptions!$B$32) -> 19096200 | I18: =H18 -> 19096200 | J18: =I18 -> 19096200 | K18: =J18*(1+Assumptions!$B$32) -> 19669086 | L18: =K18 -> 19669086 | M18: =L18 -> 19669086
A21: BASE CASE
B22: Aug-26 | C22: Sep-26 | D22: Oct-26 | E22: Nov-26 | F22: Dec-26 | G22: Jan-27 | H22: Feb-27 | I22: Mar-27 | J22: Apr-27 | K22: May-27 | L22: Jun-27 | M22: Jul-27
A23: New Downloads | B23: =Assumptions!$B$10 -> 800 | C23: =B23*(1+Assumptions!$B$11) -> 864 | D23: =C23*(1+Assumptions!$B$11) -> 933.12 | E23: =D23*(1+Assumptions!$B$11) -> 1007.7696 | F23: =E23*(1+Assumptions!$B$11) -> 1088.3912 | G23: =F23*(1+Assumptions!$B$11) -> 1175.4625 | H23: =G23*(1+Assumptions!$B$11) -> 1269.4995 | I23: =H23*(1+Assumptions!$B$11) -> 1371.0594 | J23: =I23*(1+Assumptions!$B$11) -> 1480.7442 | ... M23: =L23*(1+Assumptions!$B$11) -> 1865.3112
A24: Cumulative App Users | B24: =B23 -> 800 | C24: =B24+C23 -> 1664 | D24: =C24+D23 -> 2597.12 | E24: =D24+E23 -> 3604.8896 | F24: =E24+F23 -> 4693.2808 | G24: =F24+G23 -> 5868.7432 | H24: =G24+H23 -> 7138.2427 | I24: =H24+I23 -> 8509.3021 | J24: =I24+J23 -> 9990.0463 | ... M24: =L24+M23 -> 15181.701
A25: Active Premium Subscribers | B25: =B23*Assumptions!$B$12 -> 40 | C25: =B25*(1-Assumptions!$B$14)+C23*Assumptions!$B$12 -> 81.6 | D25: =C25*(1-Assumptions!$B$14)+D23*Assumptions!$B$12 -> 124.992 | E25: =D25*(1-Assumptions!$B$14)+E23*Assumptions!$B$12 -> 170.3808 | F25: =E25*(1-Assumptions!$B$14)+F23*Assumptions!$B$12 -> 217.98513 | G25: =F25*(1-Assumptions!$B$14)+G23*Assumptions!$B$12 -> 268.03884 | H25: =G25*(1-Assumptions!$B$14)+H23*Assumptions!$B$12 -> 320.79226 | I25: =H25*(1-Assumptions!$B$14)+I23*Assumptions!$B$12 -> 376.51354 | J25: =I25*(1-Assumptions!$B$14)+J23*Assumptions!$B$12 -> 435.49021 | ... M25: =L25*(1-Assumptions!$B$14)+M23*Assumptions!$B$12 -> 635.15345
A26: Premium Revenue (₦) | B26: =B25*Assumptions!$B$13 -> 180000 | C26: =C25*Assumptions!$B$13 -> 367200 | D26: =D25*Assumptions!$B$13 -> 562464 | E26: =E25*Assumptions!$B$13 -> 766713.6 | F26: =F25*Assumptions!$B$13 -> 980933.07 | G26: =G25*Assumptions!$B$13 -> 1206174.8 | H26: =H25*Assumptions!$B$13 -> 1443565.2 | I26: =I25*Assumptions!$B$13 -> 1694310.9 | ... M26: =M25*Assumptions!$B$13 -> 2858190.5
A27: Active Schools | B27: =Assumptions!$B$17 -> 3 | C27: =B27*(1-Assumptions!$B$20)+Assumptions!$B$18 -> 4.97 | D27: =C27*(1-Assumptions!$B$20)+Assumptions!$B$18 -> 6.9203 | E27: =D27*(1-Assumptions!$B$20)+Assumptions!$B$18 -> 8.851097 | F27: =E27*(1-Assumptions!$B$20)+Assumptions!$B$18 -> 10.762586 | G27: =F27*(1-Assumptions!$B$20)+Assumptions!$B$18 -> 12.65496 | H27: =G27*(1-Assumptions!$B$20)+Assumptions!$B$18 -> 14.528411 | I27: =H27*(1-Assumptions!$B$20)+Assumptions!$B$18 -> 16.383126 | J27: =I27*(1-Assumptions!$B$20)+Assumptions!$B$18 -> 18.219295 | ... M27: =L27*(1-Assumptions!$B$20)+Assumptions!$B$18 -> 23.618364
A28: School Revenue (₦) | B28: =B27*Assumptions!$B$19 -> 675000 | C28: =C27*Assumptions!$B$19 -> 1118250 | D28: =D27*Assumptions!$B$19 -> 1557067.5 | E28: =E27*Assumptions!$B$19 -> 1991496.8 | F28: =F27*Assumptions!$B$19 -> 2421581.9 | G28: =G27*Assumptions!$B$19 -> 2847366 | H28: =H27*Assumptions!$B$19 -> 3268892.4 | I28: =I27*Assumptions!$B$19 -> 3686203.5 | ... M28: =M27*Assumptions!$B$19 -> 5314131.9
A29: Assessment Revenue (₦) | B29: =Assumptions!$B$23*Assumptions!$B$25 -> 750000 | C29: =B29*(1+Assumptions!$B$24) -> 787500 | D29: =C29*(1+Assumptions!$B$24) -> 826875 | E29: =D29*(1+Assumptions!$B$24) -> 868218.75 | F29: =E29*(1+Assumptions!$B$24) -> 911629.69 | G29: =F29*(1+Assumptions!$B$24) -> 957211.17 | H29: =G29*(1+Assumptions!$B$24) -> 1005071.7 | I29: =H29*(1+Assumptions!$B$24) -> 1055325.3 | J29: =I29*(1+Assumptions!$B$24) -> 1108091.6 | ... M29: =L29*(1+Assumptions!$B$24) -> 1282754.5
A30: Grant Revenue (₦) | B30: =0 -> 0 | C30: =0 -> 0 | D30: =Assumptions!$B$28 -> 22500000 | E30: =0 -> 0 | F30: =0 -> 0 | G30: =Assumptions!$B$28 -> 22500000 | H30: =0 -> 0 | I30: =0 -> 0 | J30: =Assumptions!$B$28 -> 22500000 | K30: =0 -> 0 | L30: =0 -> 0 | M30: =Assumptions!$B$28 -> 22500000
A31: TOTAL REVENUE (₦) | B31: =B26+B28+B29+B30 -> 1605000 | C31: =C26+C28+C29+C30 -> 2272950 | D31: =D26+D28+D29+D30 -> 25446406 | E31: =E26+E28+E29+E30 -> 3626429.2 | F31: =F26+F28+F29+F30 -> 4314144.6 | G31: =G26+G28+G29+G30 -> 27510752 | H31: =H26+H28+H29+H30 -> 5717529.3 | I31: =I26+I28+I29+I30 -> 6435839.7 | ... M31: =M26+M28+M29+M30 -> 31955077
A32: TOTAL OPEX (₦) | B32: =(B35+(Assumptions!$B$33+Assumptions!$B$34*B24)+(Assumptions!$B$35+Assumptions!$B$36*B31)+Assumptions!$B$37)*(1+Assumptions!$B$38) -> 24295320 | C32: =(C35+(Assumptions!$B$33+Assumptions!$B$34*C24)+(Assumptions!$B$35+Assumptions!$B$36*C31)+Assumptions!$B$37)*(1+Assumptions!$B$38) -> 24419468 | D32: =(D35+(Assumptions!$B$33+Assumptions!$B$34*D24)+(Assumptions!$B$35+Assumptions!$B$36*D31)+Assumptions!$B$37)*(1+Assumptions!$B$38) -> 26439521 | E32: =(E35+(Assumptions!$B$33+Assumptions!$B$34*E24)+(Assumptions!$B$35+Assumptions!$B$36*E31)+Assumptions!$B$37)*(1+Assumptions!$B$38) -> 25253005 | F32: =(F35+(Assumptions!$B$33+Assumptions!$B$34*F24)+(Assumptions!$B$35+Assumptions!$B$36*F31)+Assumptions!$B$37)*(1+Assumptions!$B$38) -> 25396484 | G32: =(G35+(Assumptions!$B$33+Assumptions!$B$34*G24)+(Assumptions!$B$35+Assumptions!$B$36*G31)+Assumptions!$B$37)*(1+Assumptions!$B$38) -> 27437567 | H32: =(H35+(Assumptions!$B$33+Assumptions!$B$34*H24)+(Assumptions!$B$35+Assumptions!$B$36*H31)+Assumptions!$B$37)*(1+Assumptions!$B$38) -> 26290919 | I32: =(I35+(Assumptions!$B$33+Assumptions!$B$34*I24)+(Assumptions!$B$35+Assumptions!$B$36*I31)+Assumptions!$B$37)*(1+Assumptions!$B$38) -> 26459228 | ... M32: =(M35+(Assumptions!$B$33+Assumptions!$B$34*M24)+(Assumptions!$B$35+Assumptions!$B$36*M31)+Assumptions!$B$37)*(1+Assumptions!$B$38) -> 29729826
A33: Net Cash Flow (₦) | B33: =B31-B32 -> -22690320 | C33: =C31-C32 -> -22146518 | D33: =D31-D32 -> -993114.85 | E33: =E31-E32 -> -21626576 | F33: =F31-F32 -> -21082339 | G33: =G31-G32 -> 73185.312 | H33: =H31-H32 -> -20573390 | I33: =I31-I32 -> -20023388 | ... M33: =M31-M32 -> 2225251.2
A34: Ending Cash Balance (₦) | B34: =Assumptions!$B$7+B33 -> 52309680 | C34: =B34+C33 -> 30163162 | D34: =C34+D33 -> 29170047 | E34: =D34+E33 -> 7543471.4 | F34: =E34+F33 -> -13538868 | G34: =F34+G33 -> -13465683 | H34: =G34+H33 -> -34039072 | I34: =H34+I33 -> -54062461 | J34: =I34+J33 -> -52922588 | ... M34: =L34+M33 -> -89164112
A35: (helper) Monthly Salaries (₦) | B35: =Assumptions!$B$31 -> 18000000 | C35: =B35 -> 18000000 | D35: =C35 -> 18000000 | E35: =D35*(1+Assumptions!$B$32) -> 18540000 | F35: =E35 -> 18540000 | G35: =F35 -> 18540000 | H35: =G35*(1+Assumptions!$B$32) -> 19096200 | I35: =H35 -> 19096200 | J35: =I35 -> 19096200 | K35: =J35*(1+Assumptions!$B$32) -> 19669086 | L35: =K35 -> 19669086 | M35: =L35 -> 19669086
A38: OPTIMISTIC CASE
B39: Aug-26 | C39: Sep-26 | D39: Oct-26 | E39: Nov-26 | F39: Dec-26 | G39: Jan-27 | H39: Feb-27 | I39: Mar-27 | J39: Apr-27 | K39: May-27 | L39: Jun-27 | M39: Jul-27
A40: New Downloads | B40: =Assumptions!$B$10 -> 800 | C40: =B40*(1+Assumptions!$D$11) -> 896 | D40: =C40*(1+Assumptions!$D$11) -> 1003.52 | E40: =D40*(1+Assumptions!$D$11) -> 1123.9424 | F40: =E40*(1+Assumptions!$D$11) -> 1258.8155 | G40: =F40*(1+Assumptions!$D$11) -> 1409.8733 | H40: =G40*(1+Assumptions!$D$11) -> 1579.0581 | I40: =H40*(1+Assumptions!$D$11) -> 1768.5451 | J40: =I40*(1+Assumptions!$D$11) -> 1980.7705 | ... M40: =L40*(1+Assumptions!$D$11) -> 2782.84
A41: Cumulative App Users | B41: =B40 -> 800 | C41: =B41+C40 -> 1696 | D41: =C41+D40 -> 2699.52 | E41: =D41+E40 -> 3823.4624 | F41: =E41+F40 -> 5082.2779 | G41: =F41+G40 -> 6492.1512 | H41: =G41+H40 -> 8071.2094 | I41: =H41+I40 -> 9839.7545 | J41: =I41+J40 -> 11820.525 | ... M41: =L41+M40 -> 19306.507
A42: Active Premium Subscribers | B42: =B40*Assumptions!$D$12 -> 56 | C42: =B42*(1-Assumptions!$D$14)+C40*Assumptions!$D$12 -> 117.04 | D42: =C42*(1-Assumptions!$D$14)+D40*Assumptions!$D$12 -> 183.7752 | E42: =D42*(1-Assumptions!$D$14)+E40*Assumptions!$D$12 -> 256.93791 | F42: =E42*(1-Assumptions!$D$14)+F40*Assumptions!$D$12 -> 337.34686 | G42: =F42*(1-Assumptions!$D$14)+G40*Assumptions!$D$12 -> 425.91759 | H42: =G42*(1-Assumptions!$D$14)+H40*Assumptions!$D$12 -> 523.67413 | I42: =H42*(1-Assumptions!$D$14)+I40*Assumptions!$D$12 -> 631.76206 | J42: =I42*(1-Assumptions!$D$14)+J40*Assumptions!$D$12 -> 751.46314 | ... M42: =L42*(1-Assumptions!$D$14)+M40*Assumptions!$D$12 -> 1195.4632
A43: Premium Revenue (₦) | B43: =B42*Assumptions!$B$13 -> 252000 | C43: =C42*Assumptions!$B$13 -> 526680 | D43: =D42*Assumptions!$B$13 -> 826988.4 | E43: =E42*Assumptions!$B$13 -> 1156220.6 | F43: =F42*Assumptions!$B$13 -> 1518060.9 | G43: =G42*Assumptions!$B$13 -> 1916629.1 | H43: =H42*Assumptions!$B$13 -> 2356533.6 | I43: =I42*Assumptions!$B$13 -> 2842929.3 | ... M43: =M42*Assumptions!$B$13 -> 5379584.5
A44: Active Schools | B44: =Assumptions!$B$17 -> 3 | C44: =B44*(1-Assumptions!$D$20)+Assumptions!$D$18 -> 5.985 | D44: =C44*(1-Assumptions!$D$20)+Assumptions!$D$18 -> 8.955075 | E44: =D44*(1-Assumptions!$D$20)+Assumptions!$D$18 -> 11.9103 | F44: =E44*(1-Assumptions!$D$20)+Assumptions!$D$18 -> 14.850748 | G44: =F44*(1-Assumptions!$D$20)+Assumptions!$D$18 -> 17.776494 | H44: =G44*(1-Assumptions!$D$20)+Assumptions!$D$18 -> 20.687612 | I44: =H44*(1-Assumptions!$D$20)+Assumptions!$D$18 -> 23.584174 | J44: =I44*(1-Assumptions!$D$20)+Assumptions!$D$18 -> 26.466253 | ... M44: =L44*(1-Assumptions!$D$20)+Assumptions!$D$18 -> 35.026316
A45: School Revenue (₦) | B45: =B44*Assumptions!$B$19 -> 675000 | C45: =C44*Assumptions!$B$19 -> 1346625 | D45: =D44*Assumptions!$B$19 -> 2014891.9 | E45: =E44*Assumptions!$B$19 -> 2679817.4 | F45: =F44*Assumptions!$B$19 -> 3341418.3 | G45: =G44*Assumptions!$B$19 -> 3999711.2 | H45: =H44*Assumptions!$B$19 -> 4654712.7 | I45: =I44*Assumptions!$B$19 -> 5306439.1 | ... M45: =M44*Assumptions!$B$19 -> 7880921.1
...
